Workbook
Name norma: Principal!$A$90:$B$93

Sheet Principal
C2: ORÇAMENTO - REDE DE DUTOS
I3: V. 1.0 - junho/2000
I4: V. 2.0 - agosto/2022
B6: Cliente : | D6: CONSTRUCOMPANY
B7: Obra : | D7: PEDROSO DE MORAES
B8: Sistema : | D8: EXAUSTÃO
B9: Orçamento nº : | D9: 23.31107PRC
C11: Levantamento
F12: Norma : | G12: 1 | H12: =IF(G12<>"",(VLOOKUP(G12,norma,2,FALSE)),"") -> ABNT | J12: =Resumo!$E$15 -> 27 | K12: kg
F14: Valor M. O. /kg : | G14: 18 | H14: (acima de 500 kg)
C15: Resumo
F16: Folga - chapa : | G16: =IF(Calculos!$G$303>10000,15,20) -> 20 | H16: % | I16: R$ | J16: =Resumo!$H$62 -> 564 | K16: Material
I18: R$ | J18: =Resumo!$H$64 -> 972 | K18: M. Obra
C19: Calculos
F20: Folga - isolamento : | G20: 15 | H20: %
C23: Tabelas de Preços
F24: Folga - suportes : | G24: 30 | H24: %
A90: 1 | B90: ABNT
A91: 2 | B91: ABNT v.2008
A92: 3 | B92: ABNT (c/ reforço TR)

Sheet Levantamento dutos
B1: Retorna | H1: =Principal!I4 -> V. 2.0 - agosto/2022
B2: Cliente : | D2: =Principal!D6 -> CONSTRUCOMPANY
B3: Obra : | D3: =Principal!D7 -> PEDROSO DE MORAES
B4: Sistema : | D4: =Principal!D8 -> EXAUSTÃO
B5: Orçamento nº : | D5: =IF(Principal!D9<>"",Principal!D9,"") -> 23.31107PRC
A7: TAG | B7: Lado Maior (cm) | C7: Lado Menor (cm) | D7: Comprimento (m) | E7: L = Manta lã vidro | F7: Isolamento Interno | G7: Flange | H7: Rechapeado | I7: Pintura no Rechapeado
E8: I = Isopor | F8: B = Bidim | G8: P = Powermatic | H8: S = sim | I8: S = sim
E9: P = Placa lã vidro | F9: F = Flexiliner | G9: C = Cantoneira | H9: N = não | I9: N = não
E10: T = Pintura | F10: S = sem isol. | G10: S = sem flange
E11: espessura (mm) | G11: espaçamento (m) | H11: espessura (mm)
E12: 25 | G12: 1 | H12: =E12 -> 25
B13: 40 | C13: 25 | D13: 3 | E13: S = sem isolamento | F13: S = sem isol. | G13: P = Powermatic | H13: N = não | I13: N = não
E14: S = sem isolamento | F14: S = sem isol. | G14: P = Powermatic | H14: N = não | I14: N = não
E15: S = sem isolamento | F15: S = sem isol. | G15: P = Powermatic | H15: N = não | I15: N = não
E16: S = sem isolamento | F16: S = sem isol. | G16: P = Powermatic | H16: N = não | I16: N = não
E17: S = sem isolamento | F17: S = sem isol. | G17: P = Powermatic | H17: N = não | I17: N = não
E18: S = sem isolamento | F18: S = sem isol. | G18: P = Powermatic | H18: N = não | I18: N = não
E19: S = sem isolamento | F19: S = sem isol. | G19: P = Powermatic | H19: N = não | I19: N = não
E20: S = sem isolamento | F20: S = sem isol. | G20: P = Powermatic | H20: N = não | I20: N = não
E21: S = sem isolamento | F21: S = sem isol. | G21: P = Powermatic | H21: N = não | I21: N = não
E22: S = sem isolamento | F22: S = sem isol. | G22: P = Powermatic | H22: N = não | I22: N = não
E23: S = sem isolamento | F23: S = sem isol. | G23: P = Powermatic | H23: N = não | I23: N = não
E24: S = sem isolamento | F24: S = sem isol. | G24: P = Powermatic | H24: N = não | I24: N = não
E25: S = sem isolamento | F25: S = sem isol. | G25: P = Powermatic | H25: N = não | I25: N = não
... E50: S = sem isolamento | F50: S = sem isol. | G50: P = Powermatic | H50: N = não | I50: N = não
B51: 0 | C51: 0 | D51: 0 | E51: S = sem isolamento | F51: S = sem isol. | G51: S = sem flange | H51: N = não | I51: N = não
B52: 0 | C52: 0 | D52: 0 | E52: S = sem isolamento | F52: S = sem isol. | G52: S = sem flange | H52: N = não | I52: N = não
B53: 0 | C53: 0 | D53: 0 | E53: S = sem isolamento | F53: S = sem isol. | G53: S = sem flange | H53: N = não | I53: N = não
B54: 0 | C54: 0 | D54: 0 | E54: S = sem isolamento | F54: S = sem isol. | G54: S = sem flange | H54: N = não | I54: N = não
B55: 0 | C55: 0 | D55: 0 | E55: S = sem isolamento | F55: S = sem isol. | G55: S = sem flange | H55: N = não | I55: N = não
B56: 0 | C56: 0 | D56: 0 | E56: S = sem isolamento | F56: S = sem isol. | G56: S = sem flange | H56: N = não | I56: N = não
B57: 0 | C57: 0 | D57: 0 | E57: S = sem isolamento | F57: S = sem isol. | G57: S = sem flange | H57: N = não | I57: N = não
B58: 0 | C58: 0 | D58: 0 | E58: S = sem isolamento | F58: S = sem isol. | G58: S = sem flange | H58: N = não | I58: N = não
B59: 0 | C59: 0 | D59: 0 | E59: S = sem isolamento | F59: S = sem isol. | G59: S = sem flange | H59: N = não | I59: N = não
B60: 0 | C60: 0 | D60: 0 | E60: S = sem isolamento | F60: S = sem isol. | G60: S = sem flange | H60: N = não | I60: N = não
B61: 0 | C61: 0 | D61: 0 | E61: S = sem isolamento | F61: S = sem isol. | G61: S = sem flange | H61: N = não | I61: N = não
B62: 0 | C62: 0 | D62: 0 | E62: S = sem isolamento | F62: S = sem isol. | G62: S = sem flange | H62: N = não | I62: N = não
... B300: 0 | C300: 0 | D300: 0 | E300: S = sem isolamento | F300: S = sem isol. | G300: S = sem flange | H300: N = não | I300: N = não
B301: 0 | C301: 0 | D301: 0
B302: 0 | C302: 0 | D302: 0
...

Sheet Resumo
B1: Retorna | I1: =Principal!I4 -> V. 2.0 - agosto/2022
B2: Cliente : | D2: =IF(Principal!D6<>"",Principal!D6,"") -> CONSTRUCOMPANY
B3: Obra : | D3: =IF(Principal!D7<>"",Principal!D7,"") -> PEDROSO DE MORAES
B4: Sistema : | D4: =IF(Principal!D8<>"",Principal!D8,"") -> EXAUSTÃO
B5: Orçamento nº : | D5: =IF(Principal!D9<>"",Principal!D9,"") -> 23.31107PRC
B7: Chapas Galvanizadas | D7: Unid. | E7: Qtde | F7: Preço unitário (R$) | H7: Preço total (R$)
B8: # 26 | D8: kg | E8: =ROUND(Calculos!$B$304,0) -> 0 | F8: =Tab_Precos!$E4 -> 17 | H8: =F8*E8 -> 0
B9: # 24 | D9: kg | E9: =ROUND(Calculos!$C$304,0) -> 27 | F9: =Tab_Precos!$E5 -> 17 | H9: =F9*E9 -> 459
B10: # 22 | D10: kg | E10: =ROUND(Calculos!$D$304,0) -> 0 | F10: =Tab_Precos!$E6 -> 17 | H10: =F10*E10 -> 0
B11: # 20 | D11: kg | E11: =ROUND(Calculos!$E$304,0) -> 0 | F11: =Tab_Precos!$E7 -> 17 | H11: =F11*E11 -> 0
B12: # 18 | D12: kg | E12: =ROUND(Calculos!$F$304,0) -> 0 | F12: =Tab_Precos!$E8 -> 17 | H12: =F12*E12 -> 0
B13: # 26 (rechapeamento) | D13: kg | E13: =ROUND(Calculos!$Q$304,0) -> 0 | F13: =Tab_Precos!$E9 -> 17 | H13: =F13*E13 -> 0
B14: # 26 (cantoneira) | D14: kg | E14: =ROUND(Calculos!AD304+Calculos!AE304,0) -> 0 | F14: =Tab_Precos!$E10 -> 17 | H14: =F14*E14 -> 0
D15: kg | E15: =SUM(E8:E14) -> 27 | H15: =SUM(H8:I14) -> 459
B17: Isolamento | D17: Unid. | E17: Qtde | F17: Preço unitário (R$) | H17: Preço total (R$)
B18: Isopor F1 | D18: m² | E18: =ROUND(Calculos!$I$304,0) -> 0 | F18: =Tab_Precos!$E14 -> 6.6 | H18: =F18*E18 -> 0
B19: Manta lã de vidro | D19: m² | E19: =ROUND(Calculos!$H$304,0) -> 0 | F19: =Tab_Precos!$E15 -> 15 | H19: =F19*E19 -> 0
B20: Placa lã de vidro | D20: m² | E20: =ROUND(Calculos!$J$304,0) -> 0 | F20: =Tab_Precos!$E16 -> 130 | H20: =F20*E20 -> 0
B21: Bidim OP-60 | D21: m² | E21: =ROUND(Calculos!K304,0) -> 0 | F21: =Tab_Precos!$E17 -> 6 | H21: =F21*E21 -> 0
B22: Flexiliner | D22: m² | E22: =ROUND(Calculos!$L$304,0) -> 0 | F22: =Tab_Precos!$E18 -> 17.53 | H22: =F22*E22 -> 0
B23: Cola HI-17 ou Over-cola | D23: gl | E23: =ROUND(((E18+E19+E20+E21)*0.45)/3.6,0) -> 0 | F23: =Tab_Precos!$E19 -> 15.5 | H23: =F23*E23 -> 0
B24: Frio Asfalto | D24: bd | E24: =ROUND(E18/80,0) -> 0 | F24: =Tab_Precos!$E20 -> 62.66 | H24: =F24*E24 -> 0
B25: Fita de Nylon ½" | D25: m | E25: =SUM(Calculos!T304:V304) -> 0 | F25: =Tab_Precos!$E21 -> 0.03 | H25: =F25*E25 -> 0
B26: Fecho p/ fita de nylon ½" | D26: pç | E26: =SUM(Calculos!W304:Y304) -> 0 | F26: =Tab_Precos!$E22 -> 0.1 | H26: =F26*E26 -> 0
B27: Fita aluminizada | D27: m | E27: =Calculos!$Z$304 -> 0 | F27: =Tab_Precos!$E23 -> 0.1 | H27: =F27*E27 -> 0
H28: =F28*E28 -> 0
E29: 1 | F29: 0 | H29: =F29*E29 -> 0
D30: m² | E30: =SUM(E18:E20) -> 0 | H30: =SUM(H18:I29) -> 0
B32: Pintura | D32: Unid. | E32: Qtde | F32: Preço unitário (R$) | H32: Preço total (R$)
B33: Tinta de fundo - Zarcão | D33: gl | E33: =ROUND(E37/25,0) -> 0 | F33: =Tab_Precos!$E29 -> 95 | H33: =F33*E33 -> 0
B34: Tinta Acabamento | D34: gl | E34: =ROUND((E37/20)*2,0) -> 0 | F34: =Tab_Precos!$E30 -> 150 | H34: =F34*E34 -> 0
B35: Trincha / rolinho | D35: pç | E35: =ROUND((E33+E34)/10,0) -> 0 | F35: =Tab_Precos!$E31 -> 6 | H35: =F35*E35 -> 0
B36: Tinner | D36: l | E36: =ROUND((E33+E34)/0.5,0) -> 0 | F36: =Tab_Precos!$E32 -> 12 | H36: =F36*E36 -> 0
D37: m² | E37: =ROUND(Calculos!$M$304+Calculos!$S$304,0) -> 0 | H37: =SUM(H33:I36) -> 0
B39: Suportes | D39: Unid. | E39: Qtde | F39: Preço unitário (R$) | H39: Preço total (R$)
B40: Suportes | D40: kg | E40: =ROUND($E$15*Principal!G24/100,0) -> 8 | F40: =Tab_Precos!$E36 -> 2 | H40: =F40*E40 -> 16
D41: kg | E41: =E40 -> 8 | H41: =H40 -> 16
B43: Acessórios | D43: Unid. | E43: Qtde | F43: Preço unitário (R$) | H43: Preço total (R$)
B44: Spliters | D44: pç | F44: =Tab_Precos!$E40 -> 14 | H44: =F44*E44 -> 0
B45: Captor c/ Haste Articulada | D45: pç | F45: =Tab_Precos!$E41 -> 9.6 | H45: =F45*E45 -> 0
...

Sheet Calculos
B2: Chapa | C2: Peso (kg/m²) | D2: ABNT | F2: ABNT (v.2008) | H2: ABNT (c/ reforço TR) | Z2: =Principal!H12 -> ABNT
B3: # 26 | C3: 4.5 | D3: até | E3: 30 | F3: até | G3: 70 | H3: até | I3: 90 | Z3: =SUM(AA3:AD3) -> 30 | AA3: =IF(Principal!$G$12=1,Calculos!E3,"") -> 30 | AB3: =IF(Principal!$G$12=2,Calculos!G3,"") | AC3: =IF(Principal!$G$12=3,Calculos!I3,"") | AD3: =IF(Principal!$G$12=4,Calculos!K3,"")
B4: # 24 | C4: 5.7 | D4: até | E4: 75 | F4: até | G4: 90 | H4: até | I4: 120 | Z4: =SUM(AA4:AD4) -> 75 | AA4: =IF(Principal!$G$12=1,Calculos!E4,"") -> 75 | AB4: =IF(Principal!$G$12=2,Calculos!G4,"") | AC4: =IF(Principal!$G$12=3,Calculos!I4,"") | AD4: =IF(Principal!$G$12=4,Calculos!K4,"")
B5: # 22 | C5: 6.8 | D5: até | E5: 140 | F5: até | G5: 120 | H5: até | I5: 150 | Z5: =SUM(AA5:AD5) -> 140 | AA5: =IF(Principal!$G$12=1,Calculos!E5,"") -> 140 | AB5: =IF(Principal!$G$12=2,Calculos!G5,"") | AC5: =IF(Principal!$G$12=3,Calculos!I5,"") | AD5: =IF(Principal!$G$12=4,Calculos!K5,"")
B6: # 20 | C6: 8.1 | D6: até | E6: 210 | F6: até | G6: 150 | H6: até | I6: 180 | Z6: =SUM(AA6:AD6) -> 210 | AA6: =IF(Principal!$G$12=1,Calculos!E6,"") -> 210 | AB6: =IF(Principal!$G$12=2,Calculos!G6,"") | AC6: =IF(Principal!$G$12=3,Calculos!I6,"") | AD6: =IF(Principal!$G$12=4,Calculos!K6,"")
B7: # 18 | C7: 10.5 | D7: acima de | E7: =E6 -> 210 | F7: acima de | G7: 150 | H7: acima de | I7: 180 | Z7: =SUM(AA7:AD7) -> 210 | AA7: =IF(Principal!$G$12=1,Calculos!E7,"") -> 210 | AB7: =IF(Principal!$G$12=2,Calculos!G7,"") | AC7: =IF(Principal!$G$12=3,Calculos!I7,"") | AD7: =IF(Principal!$G$12=4,Calculos!K7,"")
B10: # 26 | C10: # 24 | D10: # 22 | E10: # 20 | F10: # 18 | H10: Manta | I10: Isopor | J10: Placa | K10: Bidim | L10: Flexiliner | M10: Pintura | N10: Powermatic | O10: Powermatic | P10: Flange | Q10: Rechapeado | S10: Pintura | T10: Fita Plast | U10: Fita Plast | V10: Fita Plast | W10: Selo | X10: Selo | Y10: Selo | Z10: fita Alum | AA10: Canto | AB10: Grampo | AC10: Flange cant | AD10: Cantoneira | AE10: Cantoneira
B11: 4,5 kg/m² | C11: 5,7 kg/m² | D11: 6,8 kg/m² | E11: 8,1 kg/m² | F11: 10,5 kg/m² | G11: perimetro | H11: lã de vidro | J11: lã de vidro | N11: PW1 | O11: PW2 | P11: cantoneira | Q11: # 26 | S11: Rechap | T11: manta | U11: isopor | V11: placa | W11: manta | X11: isopor | Y11: placa | Z11: manta | AA11: Powerm | AB11: Powerm | AC11: (acima 2,20 m) | AD11: isopor # 26 | AE11: placa # 26
B12: (m²) | C12: (m²) | D12: (m²) | E12: (m²) | F12: (m²) | G12: (m) | H12: (m²) | I12: (m²) | J12: (m²) | K12: (m²) | L12: (m²) | M12: (m²) | N12: (m) | O12: (m) | P12: (m) | Q12: (m²) | S12: (m²) | T12: (m) | U12: (m) | V12: (m) | W12: (pç) | X12: (pç) | Y12: (pç) | Z12: (m) | AA12: (pç) | AB12: (pç) | AC12: (m) | AD12: (m²) | AE12: (m²)
B13: =IF('Levantamento dutos'!$B13<=Calculos!$Z$3,((('Levantamento dutos'!$B13)/100+('Levantamento dutos'!$C13)/100)*2)*'Levantamento dutos'!$D13,0) -> 0 | C13: =IF('Levantamento dutos'!$B13>Calculos!$Z$3,IF('Levantamento dutos'!$B13<=Calculos!$Z$4,((('Levantamento dutos'!$B13)/100+('Levantamento dutos'!$C13)/100)*2)*'Levantamento dutos'!$D13,0),0) -> 3.9 | D13: =IF('Levantamento dutos'!$B13>Calculos!$Z$4,IF('Levantamento dutos'!$B13<=Calculos!$Z$5,((('Levantamento dutos'!$B13)/100+('Levantamento dutos'!$C13)/100)*2)*'Levantamento dutos'!$D13,0),0) -> 0 | E13: =IF('Levantamento dutos'!$B13>Calculos!$Z$5,IF('Levantamento dutos'!$B13<=Calculos!$Z$6,((('Levantamento dutos'!$B13)/100+('Levantamento dutos'!$C13)/100)*2)*'Levantamento dutos'!$D13,0),0) -> 0 | F13: =IF('Levantamento dutos'!$B13>Calculos!$Z$7,((('Levantamento dutos'!$B13)/100+('Levantamento dutos'!$C13)/100)*2)*'Levantamento dutos'!$D13,0) -> 0 | G13: =(('Levantamento dutos'!B13+'Levantamento dutos'!C13)/100)*2 -> 1.3 | H13: =IF(CODE('Levantamento dutos'!$E13)=76,SUM($B13:$F13),0) -> 0 | I13: =IF(CODE('Levantamento dutos'!$E13)=73,SUM($B13:$F13),0) -> 0 | J13: =IF(CODE('Levantamento dutos'!$E13)=80,SUM($B13:$F13),0) -> 0 | K13: =IF(CODE('Levantamento dutos'!$F13)=66,SUM($B13:$F13),0) -> 0 | L13: =IF(CODE('Levantamento dutos'!$F13)=70,SUM($B13:$F13),0) -> 0 | M13: =IF(CODE('Levantamento dutos'!$E13)=84,SUM($B13:$F13),0) -> 0 | N13: =IF(CODE('Levantamento dutos'!$G13)=80,IF('Levantamento dutos'!$B13<=200,('Levantamento dutos'!$D13/'Levantamento dutos'!$G$12*Calculos!$G13*2),0),0) -> 7.8 | O13: =IF(CODE('Levantamento dutos'!$G13)=80,IF('Levantamento dutos'!$B13>200,('Levantamento dutos'!$D13/'Levantamento dutos'!$G$12*Calculos!$G13*2),0),0) -> 0 | P13: =IF(CODE('Levantamento dutos'!$G13)=67,('Levantamento dutos'!$D13/'Levantamento dutos'!$G$12*Calculos!$G13*2),0) -> 0 | Q13: =IF(CODE('Levantamento dutos'!H13)=83,((('Levantamento dutos'!B13/100)+('Levantamento dutos'!$H$12/1000))+(('Levantamento dutos'!C13/100)+('Levantamento dutos'!$H$12)/1000))*2*'Levantamento dutos'!D13,0) -> 0 | S13: =IF(CODE('Levantamento dutos'!$I13)=83,$Q13,0) -> 0 | T13: =IF(CODE('Levantamento dutos'!$E13)=76,ROUND((('Levantamento dutos'!$D13/0.5)*(Calculos!$G13+0.2)*1.2),0),0) -> 0 | U13: =IF(CODE('Levantamento dutos'!$E13)=73,ROUND((('Levantamento dutos'!$D13/0.5)*(Calculos!$G13+0.2)*1.2),0),0) -> 0 | V13: =IF(CODE('Levantamento dutos'!$E13)=80,ROUND((('Levantamento dutos'!$D13/0.5)*(Calculos!$G13+0.2)*1.2),0),0) -> 0 | W13: =IF(CODE('Levantamento dutos'!$E13)=76,'Levantamento dutos'!$D13/0.5*1.5,0) -> 0 | X13: =IF(CODE('Levantamento dutos'!$E13)=73,'Levantamento dutos'!$D13/0.5*1.5,0) -> 0 | Y13: =IF(CODE('Levantamento dutos'!$E13)=80,'Levantamento dutos'!$D13/0.5*1.5,0) -> 0 | Z13: =IF(CODE('Levantamento dutos'!$E13)=76,ROUND(('Levantamento dutos'!$D13)+('Levantamento dutos'!$D13*Calculos!$G13*2)*1.1,0),0) -> 0 | AA13: =IF(CODE('Levantamento dutos'!$G13)=80,('Levantamento dutos'!$D13/'Levantamento dutos'!$G$12)*8,0) -> 24 | AB13: =IF(CODE('Levantamento dutos'!$G13)=80,IF('Levantamento dutos'!$B13>30,('Levantamento dutos'!$D13/'Levantamento dutos'!$G$12)*4,0),0) -> 12 | AC13: =IF('Levantamento dutos'!$B13>220,('Levantamento dutos'!$D13/'Levantamento dutos'!$G$12*Calculos!$G13*2),0) -> 0 | AD13: =IF(CODE('Levantamento dutos'!$E13)=73,((('Levantamento dutos'!$E$12/1000)+0.02)*'Levantamento dutos'!$D13)*4*1.3,0) -> 0 | AE13: =IF(CODE('Levantamento dutos'!$E13)=80,((('Levantamento dutos'!$E$12/1000)+0.02)*'Levantamento dutos'!$D13)*4*1.3,0) -> 0
B14: =IF('Levantamento dutos'!$B14<=Calculos!$Z$3,((('Levantamento dutos'!$B14)/100+('Levantamento dutos'!$C14)/100)*2)*'Levantamento dutos'!$D14,0) -> 0 | C14: =IF('Levantamento dutos'!$B14>Calculos!$Z$3,IF('Levantamento dutos'!$B14<=Calculos!$Z$4,((('Levantamento dutos'!$B14)/100+('Levantamento dutos'!$C14)/100)*2)*'Levantamento dutos'!$D14,0),0) -> 0 | D14: =IF('Levantamento dutos'!$B14>Calculos!$Z$4,IF('Levantamento dutos'!$B14<=Calculos!$Z$5,((('Levantamento dutos'!$B14)/100+('Levantamento dutos'!$C14)/100)*2)*'Levantamento dutos'!$D14,0),0) -> 0 | E14: =IF('Levantamento dutos'!$B14>Calculos!$Z$5,IF('Levantamento dutos'!$B14<=Calculos!$Z$6,((('Levantamento dutos'!$B14)/100+('Levantamento dutos'!$C14)/100)*2)*'Levantamento dutos'!$D14,0),0) -> 0 | F14: =IF('Levantamento dutos'!$B14>Calculos!$Z$7,((('Levantamento dutos'!$B14)/100+('Levantamento dutos'!$C14)/100)*2)*'Levantamento dutos'!$D14,0) -> 0 | G14: =(('Levantamento dutos'!B14+'Levantamento dutos'!C14)/100)*2 -> 0 | H14: =IF(CODE('Levantamento dutos'!$E14)=76,SUM($B14:$F14),0) -> 0 | I14: =IF(CODE('Levantamento dutos'!$E14)=73,SUM($B14:$F14),0) -> 0 | J14: =IF(CODE('Levantamento dutos'!$E14)=80,SUM($B14:$F14),0) -> 0 | K14: =IF(CODE('Levantamento dutos'!$F14)=66,SUM($B14:$F14),0) -> 0 | L14: =IF(CODE('Levantamento dutos'!$F14)=70,SUM($B14:$F14),0) -> 0 | M14: =IF(CODE('Levantamento dutos'!$E14)=84,SUM($B14:$F14),0) -> 0 | N14: =IF(CODE('Levantamento dutos'!$G14)=80,IF('Levantamento dutos'!$B14<=200,('Levantamento dutos'!$D14/'Levantamento dutos'!$G$12*Calculos!$G14*2),0),0) -> 0 | O14: =IF(CODE('Levantamento dutos'!$G14)=80,IF('Levantamento dutos'!$B14>200,('Levantamento dutos'!$D14/'Levantamento dutos'!$G$12*Calculos!$G14*2),0),0) -> 0 | P14: =IF(CODE('Levantamento dutos'!$G14)=67,('Levantamento dutos'!$D14/'Levantamento dutos'!$G$12*Calculos!$G14*2),0) -> 0 | Q14: =IF(CODE('Levantamento dutos'!H14)=83,((('Levantamento dutos'!B14/100)+('Levantamento dutos'!$H$12/1000))+(('Levantamento dutos'!C14/100)+('Levantamento dutos'!$H$12)/1000))*2*'Levantamento dutos'!D14,0) -> 0 | S14: =IF(CODE('Levantamento dutos'!$I14)=83,$Q14,0) -> 0 | T14: =IF(CODE('Levantamento dutos'!$E14)=76,ROUND((('Levantamento dutos'!$D14/5)*(Calculos!$G14+0.2)*1.2),0),0) -> 0 | U14: =IF(CODE('Levantamento dutos'!$E14)=73,ROUND((('Levantamento dutos'!$D14/0.5)*(Calculos!$G14+0.2)*1.2),0),0) -> 0 | V14: =IF(CODE('Levantamento dutos'!$E14)=80,ROUND((('Levantamento dutos'!$D14/0.5)*(Calculos!$G14+0.2)*1.2),0),0) -> 0 | W14: =IF(CODE('Levantamento dutos'!$E14)=76,'Levantamento dutos'!$D14/0.5*1.5,0) -> 0 | X14: =IF(CODE('Levantamento dutos'!$E14)=73,'Levantamento dutos'!$D14/0.5*1.5,0) -> 0 | Y14: =IF(CODE('Levantamento dutos'!$E14)=80,'Levantamento dutos'!$D14/0.5*1.5,0) -> 0 | Z14: =IF(CODE('Levantamento dutos'!$E14)=76,ROUND(('Levantamento dutos'!$D14)+('Levantamento dutos'!$D14*Calculos!$G14*2)*1.1,0),0) -> 0 | AA14: =IF(CODE('Levantamento dutos'!$G14)=80,('Levantamento dutos'!$D14/'Levantamento dutos'!$G$12)*8,0) -> 0 | AB14: =IF(CODE('Levantamento dutos'!$G14)=80,IF('Levantamento dutos'!$B14>30,('Levantamento dutos'!$D14/'Levantamento dutos'!$G$12)*4,0),0) -> 0 | AC14: =IF('Levantamento dutos'!$B14>220,('Levantamento dutos'!$D14/'Levantamento dutos'!$G$12*Calculos!$G14*2),0) -> 0 | AD14: =IF(CODE('Levantamento dutos'!$E14)=73,((('Levantamento dutos'!$E$12/1000)+0.02)*'Levantamento dutos'!$D14)*4*1.3,0) -> 0 | AE14: =IF(CODE('Levantamento dutos'!$E14)=80,((('Levantamento dutos'!$E$12/1000)+0.02)*'Levantamento dutos'!$D14)*4*1.3,0) -> 0
B15: =IF('Levantamento dutos'!$B15<=Calculos!$Z$3,((('Levantamento dutos'!$B15)/100+('Levantamento dutos'!$C15)/100)*2)*'Levantamento dutos'!$D15,0) -> 0 | C15: =IF('Levantamento dutos'!$B15>Calculos!$Z$3,IF('Levantamento dutos'!$B15<=Calculos!$Z$4,((('Levantamento dutos'!$B15)/100+('Levantamento dutos'!$C15)/100)*2)*'Levantamento dutos'!$D15,0),0) -> 0 | D15: =IF('Levantamento dutos'!$B15>Calculos!$Z$4,IF('Levantamento dutos'!$B15<=Calculos!$Z$5,((('Levantamento dutos'!$B15)/100+('Levantamento dutos'!$C15)/100)*2)*'Levantamento dutos'!$D15,0),0) -> 0 | E15: =IF('Levantamento dutos'!$B15>Calculos!$Z$5,IF('Levantamento dutos'!$B15<=Calculos!$Z$6,((('Levantamento dutos'!$B15)/100+('Levantamento dutos'!$C15)/100)*2)*'Levantamento dutos'!$D15,0),0) -> 0 | F15: =IF('Levantamento dutos'!$B15>Calculos!$Z$7,((('Levantamento dutos'!$B15)/100+('Levantamento dutos'!$C15)/100)*2)*'Levantamento dutos'!$D15,0) -> 0 | G15: =(('Levantamento dutos'!B15+'Levantamento dutos'!C15)/100)*2 -> 0 | H15: =IF(CODE('Levantamento dutos'!$E15)=76,SUM($B15:$F15),0) -> 0 | I15: =IF(CODE('Levantamento dutos'!$E15)=73,SUM($B15:$F15),0) -> 0 | J15: =IF(CODE('Levantamento dutos'!$E15)=80,SUM($B15:$F15),0) -> 0 | K15: =IF(CODE('Levantamento dutos'!$F15)=66,SUM($B15:$F15),0) -> 0 | L15: =IF(CODE('Levantamento dutos'!$F15)=70,SUM($B15:$F15),0) -> 0 | M15: =IF(CODE('Levantamento dutos'!$E15)=84,SUM($B15:$F15),0) -> 0 | N15: =IF(CODE('Levantamento dutos'!$G15)=80,IF('Levantamento dutos'!$B15<=200,('Levantamento dutos'!$D15/'Levantamento dutos'!$G$12*Calculos!$G15*2),0),0) -> 0 | O15: =IF(CODE('Levantamento dutos'!$G15)=80,IF('Levantamento dutos'!$B15>200,('Levantamento dutos'!$D15/'Levantamento dutos'!$G$12*Calculos!$G15*2),0),0) -> 0 | P15: =IF(CODE('Levantamento dutos'!$G15)=67,('Levantamento dutos'!$D15/'Levantamento dutos'!$G$12*Calculos!$G15*2),0) -> 0 | Q15: =IF(CODE('Levantamento dutos'!H15)=83,((('Levantamento dutos'!B15/100)+('Levantamento dutos'!$H$12/1000))+(('Levantamento dutos'!C15/100)+('Levantamento dutos'!$H$12)/1000))*2*'Levantamento dutos'!D15,0) -> 0 | S15: =IF(CODE('Levantamento dutos'!$I15)=83,$Q15,0) -> 0 | T15: =IF(CODE('Levantamento dutos'!$E15)=76,ROUND((('Levantamento dutos'!$D15/5)*(Calculos!$G15+0.2)*1.2),0),0) -> 0 | U15: =IF(CODE('Levantamento dutos'!$E15)=73,ROUND((('Levantamento dutos'!$D15/0.5)*(Calculos!$G15+0.2)*1.2),0),0) -> 0 | V15: =IF(CODE('Levantamento dutos'!$E15)=80,ROUND((('Levantamento dutos'!$D15/0.5)*(Calculos!$G15+0.2)*1.2),0),0) -> 0 | W15: =IF(CODE('Levantamento dutos'!$E15)=76,'Levantamento dutos'!$D15/0.5*1.5,0) -> 0 | X15: =IF(CODE('Levantamento dutos'!$E15)=73,'Levantamento dutos'!$D15/0.5*1.5,0) -> 0 | Y15: =IF(CODE('Levantamento dutos'!$E15)=80,'Levantamento dutos'!$D15/0.5*1.5,0) -> 0 | Z15: =IF(CODE('Levantamento dutos'!$E15)=76,ROUND(('Levantamento dutos'!$D15)+('Levantamento dutos'!$D15*Calculos!$G15*2)*1.1,0),0) -> 0 | AA15: =IF(CODE('Levantamento dutos'!$G15)=80,('Levantamento dutos'!$D15/'Levantamento dutos'!$G$12)*8,0) -> 0 | AB15: =IF(CODE('Levantamento dutos'!$G15)=80,IF('Levantamento dutos'!$B15>30,('Levantamento dutos'!$D15/'Levantamento dutos'!$G$12)*4,0),0) -> 0 | AC15: =IF('Levantamento dutos'!$B15>220,('Levantamento dutos'!$D15/'Levantamento dutos'!$G$12*Calculos!$G15*2),0) -> 0 | AD15: =IF(CODE('Levantamento dutos'!$E15)=73,((('Levantamento dutos'!$E$12/1000)+0.02)*'Levantamento dutos'!$D15)*4*1.3,0) -> 0 | AE15: =IF(CODE('Levantamento dutos'!$E15)=80,((('Levantamento dutos'!$E$12/1000)+0.02)*'Levantamento dutos'!$D15)*4*1.3,0) -> 0
B16: =IF('Levantamento dutos'!$B16<=Calculos!$Z$3,((('Levantamento dutos'!$B16)/100+('Levantamento dutos'!$C16)/100)*2)*'Levantamento dutos'!$D16,0) -> 0 | C16: =IF('Levantamento dutos'!$B16>Calculos!$Z$3,IF('Levantamento dutos'!$B16<=Calculos!$Z$4,((('Levantamento dutos'!$B16)/100+('Levantamento dutos'!$C16)/100)*2)*'Levantamento dutos'!$D16,0),0) -> 0 | D16: =IF('Levantamento dutos'!$B16>Calculos!$Z$4,IF('Levantamento dutos'!$B16<=Calculos!$Z$5,((('Levantamento dutos'!$B16)/100+('Levantamento dutos'!$C16)/100)*2)*'Levantamento dutos'!$D16,0),0) -> 0 | E16: =IF('Levantamento dutos'!$B16>Calculos!$Z$5,IF('Levantamento dutos'!$B16<=Calculos!$Z$6,((('Levantamento dutos'!$B16)/100+('Levantamento dutos'!$C16)/100)*2)*'Levantamento dutos'!$D16,0),0) -> 0 | F16: =IF('Levantamento dutos'!$B16>Calculos!$Z$7,((('Levantamento dutos'!$B16)/100+('Levantamento dutos'!$C16)/100)*2)*'Levantamento dutos'!$D16,0) -> 0 | G16: =(('Levantamento dutos'!B16+'Levantamento dutos'!C16)/100)*2 -> 0 | H16: =IF(CODE('Levantamento dutos'!$E16)=76,SUM($B16:$F16),0) -> 0 | I16: =IF(CODE('Levantamento dutos'!$E16)=73,SUM($B16:$F16),0) -> 0 | J16: =IF(CODE('Levantamento dutos'!$E16)=80,SUM($B16:$F16),0) -> 0 | K16: =IF(CODE('Levantamento dutos'!$F16)=66,SUM($B16:$F16),0) -> 0 | L16: =IF(CODE('Levantamento dutos'!$F16)=70,SUM($B16:$F16),0) -> 0 | M16: =IF(CODE('Levantamento dutos'!$E16)=84,SUM($B16:$F16),0) -> 0 | N16: =IF(CODE('Levantamento dutos'!$G16)=80,IF('Levantamento dutos'!$B16<=200,('Levantamento dutos'!$D16/'Levantamento dutos'!$G$12*Calculos!$G16*2),0),0) -> 0 | O16: =IF(CODE('Levantamento dutos'!$G16)=80,IF('Levantamento dutos'!$B16>200,('Levantamento dutos'!$D16/'Levantamento dutos'!$G$12*Calculos!$G16*2),0),0) -> 0 | P16: =IF(CODE('Levantamento dutos'!$G16)=67,('Levantamento dutos'!$D16/'Levantamento dutos'!$G$12*Calculos!$G16*2),0) -> 0 | Q16: =IF(CODE('Levantamento dutos'!H16)=83,((('Levantamento dutos'!B16/100)+('Levantamento dutos'!$H$12/1000))+(('Levantamento dutos'!C16/100)+('Levantamento dutos'!$H$12)/1000))*2*'Levantamento dutos'!D16,0) -> 0 | S16: =IF(CODE('Levantamento dutos'!$I16)=83,$Q16,0) -> 0 | T16: =IF(CODE('Levantamento dutos'!$E16)=76,ROUND((('Levantamento dutos'!$D16/5)*(Calculos!$G16+0.2)*1.2),0),0) -> 0 | U16: =IF(CODE('Levantamento dutos'!$E16)=73,ROUND((('Levantamento dutos'!$D16/0.5)*(Calculos!$G16+0.2)*1.2),0),0) -> 0 | V16: =IF(CODE('Levantamento dutos'!$E16)=80,ROUND((('Levantamento dutos'!$D16/0.5)*(Calculos!$G16+0.2)*1.2),0),0) -> 0 | W16: =IF(CODE('Levantamento dutos'!$E16)=76,'Levantamento dutos'!$D16/0.5*1.5,0) -> 0 | X16: =IF(CODE('Levantamento dutos'!$E16)=73,'Levantamento dutos'!$D16/0.5*1.5,0) -> 0 | Y16: =IF(CODE('Levantamento dutos'!$E16)=80,'Levantamento dutos'!$D16/0.5*1.5,0) -> 0 | Z16: =IF(CODE('Levantamento dutos'!$E16)=76,ROUND(('Levantamento dutos'!$D16)+('Levantamento dutos'!$D16*Calculos!$G16*2)*1.1,0),0) -> 0 | AA16: =IF(CODE('Levantamento dutos'!$G16)=80,('Levantamento dutos'!$D16/'Levantamento dutos'!$G$12)*8,0) -> 0 | AB16: =IF(CODE('Levantamento dutos'!$G16)=80,IF('Levantamento dutos'!$B16>30,('Levantamento dutos'!$D16/'Levantamento dutos'!$G$12)*4,0),0) -> 0 | AC16: =IF('Levantamento dutos'!$B16>220,('Levantamento dutos'!$D16/'Levantamento dutos'!$G$12*Calculos!$G16*2),0) -> 0 | AD16: =IF(CODE('Levantamento dutos'!$E16)=73,((('Levantamento dutos'!$E$12/1000)+0.02)*'Levantamento dutos'!$D16)*4*1.3,0) -> 0 | AE16: =IF(CODE('Levantamento dutos'!$E16)=80,((('Levantamento dutos'!$E$12/1000)+0.02)*'Levantamento dutos'!$D16)*4*1.3,0) -> 0
B17: =IF('Levantamento dutos'!$B17<=Calculos!$Z$3,((('Levantamento dutos'!$B17)/100+('Levantamento dutos'!$C17)/100)*2)*'Levantamento dutos'!$D17,0) -> 0 | C17: =IF('Levantamento dutos'!$B17>Calculos!$Z$3,IF('Levantamento dutos'!$B17<=Calculos!$Z$4,((('Levantamento dutos'!$B17)/100+('Levantamento dutos'!$C17)/100)*2)*'Levantamento dutos'!$D17,0),0) -> 0 | D17: =IF('Levantamento dutos'!$B17>Calculos!$Z$4,IF('Levantamento dutos'!$B17<=Calculos!$Z$5,((('Levantamento dutos'!$B17)/100+('Levantamento dutos'!$C17)/100)*2)*'Levantamento dutos'!$D17,0),0) -> 0 | E17: =IF('Levantamento dutos'!$B17>Calculos!$Z$5,IF('Levantamento dutos'!$B17<=Calculos!$Z$6,((('Levantamento dutos'!$B17)/100+('Levantamento dutos'!$C17)/100)*2)*'Levantamento dutos'!$D17,0),0) -> 0 | F17: =IF('Levantamento dutos'!$B17>Calculos!$Z$7,((('Levantamento dutos'!$B17)/100+('Levantamento dutos'!$C17)/100)*2)*'Levantamento dutos'!$D17,0) -> 0 | G17: =(('Levantamento dutos'!B17+'Levantamento dutos'!C17)/100)*2 -> 0 | H17: =IF(CODE('Levantamento dutos'!$E17)=76,SUM($B17:$F17),0) -> 0 | I17: =IF(CODE('Levantamento dutos'!$E17)=73,SUM($B17:$F17),0) -> 0 | J17: =IF(CODE('Levantamento dutos'!$E17)=80,SUM($B17:$F17),0) -> 0 | K17: =IF(CODE('Levantamento dutos'!$F17)=66,SUM($B17:$F17),0) -> 0 | L17: =IF(CODE('Levantamento dutos'!$F17)=70,SUM($B17:$F17),0) -> 0 | M17: =IF(CODE('Levantamento dutos'!$E17)=84,SUM($B17:$F17),0) -> 0 | N17: =IF(CODE('Levantamento dutos'!$G17)=80,IF('Levantamento dutos'!$B17<=200,('Levantamento dutos'!$D17/'Levantamento dutos'!$G$12*Calculos!$G17*2),0),0) -> 0 | O17: =IF(CODE('Levantamento dutos'!$G17)=80,IF('Levantamento dutos'!$B17>200,('Levantamento dutos'!$D17/'Levantamento dutos'!$G$12*Calculos!$G17*2),0),0) -> 0 | P17: =IF(CODE('Levantamento dutos'!$G17)=67,('Levantamento dutos'!$D17/'Levantamento dutos'!$G$12*Calculos!$G17*2),0) -> 0 | Q17: =IF(CODE('Levantamento dutos'!H17)=83,((('Levantamento dutos'!B17/100)+('Levantamento dutos'!$H$12/1000))+(('Levantamento dutos'!C17/100)+('Levantamento dutos'!$H$12)/1000))*2*'Levantamento dutos'!D17,0) -> 0 | S17: =IF(CODE('Levantamento dutos'!$I17)=83,$Q17,0) -> 0 | T17: =IF(CODE('Levantamento dutos'!$E17)=76,ROUND((('Levantamento dutos'!$D17/5)*(Calculos!$G17+0.2)*1.2),0),0) -> 0 | U17: =IF(CODE('Levantamento dutos'!$E17)=73,ROUND((('Levantamento dutos'!$D17/0.5)*(Calculos!$G17+0.2)*1.2),0),0) -> 0 | V17: =IF(CODE('Levantamento dutos'!$E17)=80,ROUND((('Levantamento dutos'!$D17/0.5)*(Calculos!$G17+0.2)*1.2),0),0) -> 0 | W17: =IF(CODE('Levantamento dutos'!$E17)=76,'Levantamento dutos'!$D17/0.5*1.5,0) -> 0 | X17: =IF(CODE('Levantamento dutos'!$E17)=73,'Levantamento dutos'!$D17/0.5*1.5,0) -> 0 | Y17: =IF(CODE('Levantamento dutos'!$E17)=80,'Levantamento dutos'!$D17/0.5*1.5,0) -> 0 | Z17: =IF(CODE('Levantamento dutos'!$E17)=76,ROUND(('Levantamento dutos'!$D17)+('Levantamento dutos'!$D17*Calculos!$G17*2)*1.1,0),0) -> 0 | AA17: =IF(CODE('Levantamento dutos'!$G17)=80,('Levantamento dutos'!$D17/'Levantamento dutos'!$G$12)*8,0) -> 0 | AB17: =IF(CODE('Levantamento dutos'!$G17)=80,IF('Levantamento dutos'!$B17>30,('Levantamento dutos'!$D17/'Levantamento dutos'!$G$12)*4,0),0) -> 0 | AC17: =IF('Levantamento dutos'!$B17>220,('Levantamento dutos'!$D17/'Levantamento dutos'!$G$12*Calculos!$G17*2),0) -> 0 | AD17: =IF(CODE('Levantamento dutos'!$E17)=73,((('Levantamento dutos'!$E$12/1000)+0.02)*'Levantamento dutos'!$D17)*4*1.3,0) -> 0 | AE17: =IF(CODE('Levantamento dutos'!$E17)=80,((('Levantamento dutos'!$E$12/1000)+0.02)*'Levantamento dutos'!$D17)*4*1.3,0) -> 0
B18: =IF('Levantamento dutos'!$B18<=Calculos!$Z$3,((('Levantamento dutos'!$B18)/100+('Levantamento dutos'!$C18)/100)*2)*'Levantamento dutos'!$D18,0) -> 0 | C18: =IF('Levantamento dutos'!$B18>Calculos!$Z$3,IF('Levantamento dutos'!$B18<=Calculos!$Z$4,((('Levantamento dutos'!$B18)/100+('Levantamento dutos'!$C18)/100)*2)*'Levantamento dutos'!$D18,0),0) -> 0 | D18: =IF('Levantamento dutos'!$B18>Calculos!$Z$4,IF('Levantamento dutos'!$B18<=Calculos!$Z$5,((('Levantamento dutos'!$B18)/100+('Levantamento dutos'!$C18)/100)*2)*'Levantamento dutos'!$D18,0),0) -> 0 | E18: =IF('Levantamento dutos'!$B18>Calculos!$Z$5,IF('Levantamento dutos'!$B18<=Calculos!$Z$6,((('Levantamento dutos'!$B18)/100+('Levantamento dutos'!$C18)/100)*2)*'Levantamento dutos'!$D18,0),0) -> 0 | F18: =IF('Levantamento dutos'!$B18>Calculos!$Z$7,((('Levantamento dutos'!$B18)/100+('Levantamento dutos'!$C18)/100)*2)*'Levantamento dutos'!$D18,0) -> 0 | G18: =(('Levantamento dutos'!B18+'Levantamento dutos'!C18)/100)*2 -> 0 | H18: =IF(CODE('Levantamento dutos'!$E18)=76,SUM($B18:$F18),0) -> 0 | I18: =IF(CODE('Levantamento dutos'!$E18)=73,SUM($B18:$F18),0) -> 0 | J18: =IF(CODE('Levantamento dutos'!$E18)=80,SUM($B18:$F18),0) -> 0 | K18: =IF(CODE('Levantamento dutos'!$F18)=66,SUM($B18:$F18),0) -> 0 | L18: =IF(CODE('Levantamento dutos'!$F18)=70,SUM($B18:$F18),0) -> 0 | M18: =IF(CODE('Levantamento dutos'!$E18)=84,SUM($B18:$F18),0) -> 0 | N18: =IF(CODE('Levantamento dutos'!$G18)=80,IF('Levantamento dutos'!$B18<=200,('Levantamento dutos'!$D18/'Levantamento dutos'!$G$12*Calculos!$G18*2),0),0) -> 0 | O18: =IF(CODE('Levantamento dutos'!$G18)=80,IF('Levantamento dutos'!$B18>200,('Levantamento dutos'!$D18/'Levantamento dutos'!$G$12*Calculos!$G18*2),0),0) -> 0 | P18: =IF(CODE('Levantamento dutos'!$G18)=67,('Levantamento dutos'!$D18/'Levantamento dutos'!$G$12*Calculos!$G18*2),0) -> 0 | Q18: =IF(CODE('Levantamento dutos'!H18)=83,((('Levantamento dutos'!B18/100)+('Levantamento dutos'!$H$12/1000))+(('Levantamento dutos'!C18/100)+('Levantamento dutos'!$H$12)/1000))*2*'Levantamento dutos'!D18,0) -> 0 | S18: =IF(CODE('Levantamento dutos'!$I18)=83,$Q18,0) -> 0 | T18: =IF(CODE('Levantamento dutos'!$E18)=76,ROUND((('Levantamento dutos'!$D18/5)*(Calculos!$G18+0.2)*1.2),0),0) -> 0 | U18: =IF(CODE('Levantamento dutos'!$E18)=73,ROUND((('Levantamento dutos'!$D18/0.5)*(Calculos!$G18+0.2)*1.2),0),0) -> 0 | V18: =IF(CODE('Levantamento dutos'!$E18)=80,ROUND((('Levantamento dutos'!$D18/0.5)*(Calculos!$G18+0.2)*1.2),0),0) -> 0 | W18: =IF(CODE('Levantamento dutos'!$E18)=76,'Levantamento dutos'!$D18/0.5*1.5,0) -> 0 | X18: =IF(CODE('Levantamento dutos'!$E18)=73,'Levantamento dutos'!$D18/0.5*1.5,0) -> 0 | Y18: =IF(CODE('Levantamento dutos'!$E18)=80,'Levantamento dutos'!$D18/0.5*1.5,0) -> 0 | Z18: =IF(CODE('Levantamento dutos'!$E18)=76,ROUND(('Levantamento dutos'!$D18)+('Levantamento dutos'!$D18*Calculos!$G18*2)*1.1,0),0) -> 0 | AA18: =IF(CODE('Levantamento dutos'!$G18)=80,('Levantamento dutos'!$D18/'Levantamento dutos'!$G$12)*8,0) -> 0 | AB18: =IF(CODE('Levantamento dutos'!$G18)=80,IF('Levantamento dutos'!$B18>30,('Levantamento dutos'!$D18/'Levantamento dutos'!$G$12)*4,0),0) -> 0 | AC18: =IF('Levantamento dutos'!$B18>220,('Levantamento dutos'!$D18/'Levantamento dutos'!$G$12*Calculos!$G18*2),0) -> 0 | AD18: =IF(CODE('Levantamento dutos'!$E18)=73,((('Levantamento dutos'!$E$12/1000)+0.02)*'Levantamento dutos'!$D18)*4*1.3,0) -> 0 | AE18: =IF(CODE('Levantamento dutos'!$E18)=80,((('Levantamento dutos'!$E$12/1000)+0.02)*'Levantamento dutos'!$D18)*4*1.3,0) -> 0
B19: =IF('Levantamento dutos'!$B19<=Calculos!$Z$3,((('Levantamento dutos'!$B19)/100+('Levantamento dutos'!$C19)/100)*2)*'Levantamento dutos'!$D19,0) -> 0 | C19: =IF('Levantamento dutos'!$B19>Calculos!$Z$3,IF('Levantamento dutos'!$B19<=Calculos!$Z$4,((('Levantamento dutos'!$B19)/100+('Levantamento dutos'!$C19)/100)*2)*'Levantamento dutos'!$D19,0),0) -> 0 | D19: =IF('Levantamento dutos'!$B19>Calculos!$Z$4,IF('Levantamento dutos'!$B19<=Calculos!$Z$5,((('Levantamento dutos'!$B19)/100+('Levantamento dutos'!$C19)/100)*2)*'Levantamento dutos'!$D19,0),0) -> 0 | E19: =IF('Levantamento dutos'!$B19>Calculos!$Z$5,IF('Levantamento dutos'!$B19<=Calculos!$Z$6,((('Levantamento dutos'!$B19)/100+('Levantamento dutos'!$C19)/100)*2)*'Levantamento dutos'!$D19,0),0) -> 0 | F19: =IF('Levantamento dutos'!$B19>Calculos!$Z$7,((('Levantamento dutos'!$B19)/100+('Levantamento dutos'!$C19)/100)*2)*'Levantamento dutos'!$D19,0) -> 0 | G19: =(('Levantamento dutos'!B19+'Levantamento dutos'!C19)/100)*2 -> 0 | H19: =IF(CODE('Levantamento dutos'!$E19)=76,SUM($B19:$F19),0) -> 0 | I19: =IF(CODE('Levantamento dutos'!$E19)=73,SUM($B19:$F19),0) -> 0 | J19: =IF(CODE('Levantamento dutos'!$E19)=80,SUM($B19:$F19),0) -> 0 | K19: =IF(CODE('Levantamento dutos'!$F19)=66,SUM($B19:$F19),0) -> 0 | L19: =IF(CODE('Levantamento dutos'!$F19)=70,SUM($B19:$F19),0) -> 0 | M19: =IF(CODE('Levantamento dutos'!$E19)=84,SUM($B19:$F19),0) -> 0 | N19: =IF(CODE('Levantamento dutos'!$G19)=80,IF('Levantamento dutos'!$B19<=200,('Levantamento dutos'!$D19/'Levantamento dutos'!$G$12*Calculos!$G19*2),0),0) -> 0 | O19: =IF(CODE('Levantamento dutos'!$G19)=80,IF('Levantamento dutos'!$B19>200,('Levantamento dutos'!$D19/'Levantamento dutos'!$G$12*Calculos!$G19*2),0),0) -> 0 | P19: =IF(CODE('Levantamento dutos'!$G19)=67,('Levantamento dutos'!$D19/'Levantamento dutos'!$G$12*Calculos!$G19*2),0) -> 0 | Q19: =IF(CODE('Levantamento dutos'!H19)=83,((('Levantamento dutos'!B19/100)+('Levantamento dutos'!$H$12/1000))+(('Levantamento dutos'!C19/100)+('Levantamento dutos'!$H$12)/1000))*2*'Levantamento dutos'!D19,0) -> 0 | S19: =IF(CODE('Levantamento dutos'!$I19)=83,$Q19,0) -> 0 | T19: =IF(CODE('Levantamento dutos'!$E19)=76,ROUND((('Levantamento dutos'!$D19/5)*(Calculos!$G19+0.2)*1.2),0),0) -> 0 | U19: =IF(CODE('Levantamento dutos'!$E19)=73,ROUND((('Levantamento dutos'!$D19/0.5)*(Calculos!$G19+0.2)*1.2),0),0) -> 0 | V19: =IF(CODE('Levantamento dutos'!$E19)=80,ROUND((('Levantamento dutos'!$D19/0.5)*(Calculos!$G19+0.2)*1.2),0),0) -> 0 | W19: =IF(CODE('Levantamento dutos'!$E19)=76,'Levantamento dutos'!$D19/0.5*1.5,0) -> 0 | X19: =IF(CODE('Levantamento dutos'!$E19)=73,'Levantamento dutos'!$D19/0.5*1.5,0) -> 0 | Y19: =IF(CODE('Levantamento dutos'!$E19)=80,'Levantamento dutos'!$D19/0.5*1.5,0) -> 0 | Z19: =IF(CODE('Levantamento dutos'!$E19)=76,ROUND(('Levantamento dutos'!$D19)+('Levantamento dutos'!$D19*Calculos!$G19*2)*1.1,0),0) -> 0 | AA19: =IF(CODE('Levantamento dutos'!$G19)=80,('Levantamento dutos'!$D19/'Levantamento dutos'!$G$12)*8,0) -> 0 | AB19: =IF(CODE('Levantamento dutos'!$G19)=80,IF('Levantamento dutos'!$B19>30,('Levantamento dutos'!$D19/'Levantamento dutos'!$G$12)*4,0),0) -> 0 | AC19: =IF('Levantamento dutos'!$B19>220,('Levantamento dutos'!$D19/'Levantamento dutos'!$G$12*Calculos!$G19*2),0) -> 0 | AD19: =IF(CODE('Levantamento dutos'!$E19)=73,((('Levantamento dutos'!$E$12/1000)+0.02)*'Levantamento dutos'!$D19)*4*1.3,0) -> 0 | AE19: =IF(CODE('Levantamento dutos'!$E19)=80,((('Levantamento dutos'!$E$12/1000)+0.02)*'Levantamento dutos'!$D19)*4*1.3,0) -> 0
B20: =IF('Levantamento dutos'!$B20<=Calculos!$Z$3,((('Levantamento dutos'!$B20)/100+('Levantamento dutos'!$C20)/100)*2)*'Levantamento dutos'!$D20,0) -> 0 | C20: =IF('Levantamento dutos'!$B20>Calculos!$Z$3,IF('Levantamento dutos'!$B20<=Calculos!$Z$4,((('Levantamento dutos'!$B20)/100+('Levantamento dutos'!$C20)/100)*2)*'Levantamento dutos'!$D20,0),0) -> 0 | D20: =IF('Levantamento dutos'!$B20>Calculos!$Z$4,IF('Levantamento dutos'!$B20<=Calculos!$Z$5,((('Levantamento dutos'!$B20)/100+('Levantamento dutos'!$C20)/100)*2)*'Levantamento dutos'!$D20,0),0) -> 0 | E20: =IF('Levantamento dutos'!$B20>Calculos!$Z$5,IF('Levantamento dutos'!$B20<=Calculos!$Z$6,((('Levantamento dutos'!$B20)/100+('Levantamento dutos'!$C20)/100)*2)*'Levantamento dutos'!$D20,0),0) -> 0 | F20: =IF('Levantamento dutos'!$B20>Calculos!$Z$7,((('Levantamento dutos'!$B20)/100+('Levantamento dutos'!$C20)/100)*2)*'Levantamento dutos'!$D20,0) -> 0 | G20: =(('Levantamento dutos'!B20+'Levantamento dutos'!C20)/100)*2 -> 0 | H20: =IF(CODE('Levantamento dutos'!$E20)=76,SUM($B20:$F20),0) -> 0 | I20: =IF(CODE('Levantamento dutos'!$E20)=73,SUM($B20:$F20),0) -> 0 | J20: =IF(CODE('Levantamento dutos'!$E20)=80,SUM($B20:$F20),0) -> 0 | K20: =IF(CODE('Levantamento dutos'!$F20)=66,SUM($B20:$F20),0) -> 0 | L20: =IF(CODE('Levantamento dutos'!$F20)=70,SUM($B20:$F20),0) -> 0 | M20: =IF(CODE('Levantamento dutos'!$E20)=84,SUM($B20:$F20),0) -> 0 | N20: =IF(CODE('Levantamento dutos'!$G20)=80,IF('Levantamento dutos'!$B20<=200,('Levantamento dutos'!$D20/'Levantamento dutos'!$G$12*Calculos!$G20*2),0),0) -> 0 | O20: =IF(CODE('Levantamento dutos'!$G20)=80,IF('Levantamento dutos'!$B20>200,('Levantamento dutos'!$D20/'Levantamento dutos'!$G$12*Calculos!$G20*2),0),0) -> 0 | P20: =IF(CODE('Levantamento dutos'!$G20)=67,('Levantamento dutos'!$D20/'Levantamento dutos'!$G$12*Calculos!$G20*2),0) -> 0 | Q20: =IF(CODE('Levantamento dutos'!H20)=83,((('Levantamento dutos'!B20/100)+('Levantamento dutos'!$H$12/1000))+(('Levantamento dutos'!C20/100)+('Levantamento dutos'!$H$12)/1000))*2*'Levantamento dutos'!D20,0) -> 0 | S20: =IF(CODE('Levantamento dutos'!$I20)=83,$Q20,0) -> 0 | T20: =IF(CODE('Levantamento dutos'!$E20)=76,ROUND((('Levantamento dutos'!$D20/5)*(Calculos!$G20+0.2)*1.2),0),0) -> 0 | U20: =IF(CODE('Levantamento dutos'!$E20)=73,ROUND((('Levantamento dutos'!$D20/0.5)*(Calculos!$G20+0.2)*1.2),0),0) -> 0 | V20: =IF(CODE('Levantamento dutos'!$E20)=80,ROUND((('Levantamento dutos'!$D20/0.5)*(Calculos!$G20+0.2)*1.2),0),0) -> 0 | W20: =IF(CODE('Levantamento dutos'!$E20)=76,'Levantamento dutos'!$D20/0.5*1.5,0) -> 0 | X20: =IF(CODE('Levantamento dutos'!$E20)=73,'Levantamento dutos'!$D20/0.5*1.5,0) -> 0 | Y20: =IF(CODE('Levantamento dutos'!$E20)=80,'Levantamento dutos'!$D20/0.5*1.5,0) -> 0 | Z20: =IF(CODE('Levantamento dutos'!$E20)=76,ROUND(('Levantamento dutos'!$D20)+('Levantamento dutos'!$D20*Calculos!$G20*2)*1.1,0),0) -> 0 | AA20: =IF(CODE('Levantamento dutos'!$G20)=80,('Levantamento dutos'!$D20/'Levantamento dutos'!$G$12)*8,0) -> 0 | AB20: =IF(CODE('Levantamento dutos'!$G20)=80,IF('Levantamento dutos'!$B20>30,('Levantamento dutos'!$D20/'Levantamento dutos'!$G$12)*4,0),0) -> 0 | AC20: =IF('Levantamento dutos'!$B20>220,('Levantamento dutos'!$D20/'Levantamento dutos'!$G$12*Calculos!$G20*2),0) -> 0 | AD20: =IF(CODE('Levantamento dutos'!$E20)=73,((('Levantamento dutos'!$E$12/1000)+0.02)*'Levantamento dutos'!$D20)*4*1.3,0) -> 0 | AE20: =IF(CODE('Levantamento dutos'!$E20)=80,((('Levantamento dutos'!$E$12/1000)+0.02)*'Levantamento dutos'!$D20)*4*1.3,0) -> 0
B21: =IF('Levantamento dutos'!$B21<=Calculos!$Z$3,((('Levantamento dutos'!$B21)/100+('Levantamento dutos'!$C21)/100)*2)*'Levantamento dutos'!$D21,0) -> 0 | C21: =IF('Levantamento dutos'!$B21>Calculos!$Z$3,IF('Levantamento dutos'!$B21<=Calculos!$Z$4,((('Levantamento dutos'!$B21)/100+('Levantamento dutos'!$C21)/100)*2)*'Levantamento dutos'!$D21,0),0) -> 0 | D21: =IF('Levantamento dutos'!$B21>Calculos!$Z$4,IF('Levantamento dutos'!$B21<=Calculos!$Z$5,((('Levantamento dutos'!$B21)/100+('Levantamento dutos'!$C21)/100)*2)*'Levantamento dutos'!$D21,0),0) -> 0 | E21: =IF('Levantamento dutos'!$B21>Calculos!$Z$5,IF('Levantamento dutos'!$B21<=Calculos!$Z$6,((('Levantamento dutos'!$B21)/100+('Levantamento dutos'!$C21)/100)*2)*'Levantamento dutos'!$D21,0),0) -> 0 | F21: =IF('Levantamento dutos'!$B21>Calculos!$Z$7,((('Levantamento dutos'!$B21)/100+('Levantamento dutos'!$C21)/100)*2)*'Levantamento dutos'!$D21,0) -> 0 | G21: =(('Levantamento dutos'!B21+'Levantamento dutos'!C21)/100)*2 -> 0 | H21: =IF(CODE('Levantamento dutos'!$E21)=76,SUM($B21:$F21),0) -> 0 | I21: =IF(CODE('Levantamento dutos'!$E21)=73,SUM($B21:$F21),0) -> 0 | J21: =IF(CODE('Levantamento dutos'!$E21)=80,SUM($B21:$F21),0) -> 0 | K21: =IF(CODE('Levantamento dutos'!$F21)=66,SUM($B21:$F21),0) -> 0 | L21: =IF(CODE('Levantamento dutos'!$F21)=70,SUM($B21:$F21),0) -> 0 | M21: =IF(CODE('Levantamento dutos'!$E21)=84,SUM($B21:$F21),0) -> 0 | N21: =IF(CODE('Levantamento dutos'!$G21)=80,IF('Levantamento dutos'!$B21<=200,('Levantamento dutos'!$D21/'Levantamento dutos'!$G$12*Calculos!$G21*2),0),0) -> 0 | O21: =IF(CODE('Levantamento dutos'!$G21)=80,IF('Levantamento dutos'!$B21>200,('Levantamento dutos'!$D21/'Levantamento dutos'!$G$12*Calculos!$G21*2),0),0) -> 0 | P21: =IF(CODE('Levantamento dutos'!$G21)=67,('Levantamento dutos'!$D21/'Levantamento dutos'!$G$12*Calculos!$G21*2),0) -> 0 | Q21: =IF(CODE('Levantamento dutos'!H21)=83,((('Levantamento dutos'!B21/100)+('Levantamento dutos'!$H$12/1000))+(('Levantamento dutos'!C21/100)+('Levantamento dutos'!$H$12)/1000))*2*'Levantamento dutos'!D21,0) -> 0 | S21: =IF(CODE('Levantamento dutos'!$I21)=83,$Q21,0) -> 0 | T21: =IF(CODE('Levantamento dutos'!$E21)=76,ROUND((('Levantamento dutos'!$D21/5)*(Calculos!$G21+0.2)*1.2),0),0) -> 0 | U21: =IF(CODE('Levantamento dutos'!$E21)=73,ROUND((('Levantamento dutos'!$D21/0.5)*(Calculos!$G21+0.2)*1.2),0),0) -> 0 | V21: =IF(CODE('Levantamento dutos'!$E21)=80,ROUND((('Levantamento dutos'!$D21/0.5)*(Calculos!$G21+0.2)*1.2),0),0) -> 0 | W21: =IF(CODE('Levantamento dutos'!$E21)=76,'Levantamento dutos'!$D21/0.5*1.5,0) -> 0 | X21: =IF(CODE('Levantamento dutos'!$E21)=73,'Levantamento dutos'!$D21/0.5*1.5,0) -> 0 | Y21: =IF(CODE('Levantamento dutos'!$E21)=80,'Levantamento dutos'!$D21/0.5*1.5,0) -> 0 | Z21: =IF(CODE('Levantamento dutos'!$E21)=76,ROUND(('Levantamento dutos'!$D21)+('Levantamento dutos'!$D21*Calculos!$G21*2)*1.1,0),0) -> 0 | AA21: =IF(CODE('Levantamento dutos'!$G21)=80,('Levantamento dutos'!$D21/'Levantamento dutos'!$G$12)*8,0) -> 0 | AB21: =IF(CODE('Levantamento dutos'!$G21)=80,IF('Levantamento dutos'!$B21>30,('Levantamento dutos'!$D21/'Levantamento dutos'!$G$12)*4,0),0) -> 0 | AC21: =IF('Levantamento dutos'!$B21>220,('Levantamento dutos'!$D21/'Levantamento dutos'!$G$12*Calculos!$G21*2),0) -> 0 | AD21: =IF(CODE('Levantamento dutos'!$E21)=73,((('Levantamento dutos'!$E$12/1000)+0.02)*'Levantamento dutos'!$D21)*4*1.3,0) -> 0 | AE21: =IF(CODE('Levantamento dutos'!$E21)=80,((('Levantamento dutos'!$E$12/1000)+0.02)*'Levantamento dutos'!$D21)*4*1.3,0) -> 0
B22: =IF('Levantamento dutos'!$B22<=Calculos!$Z$3,((('Levantamento dutos'!$B22)/100+('Levantamento dutos'!$C22)/100)*2)*'Levantamento dutos'!$D22,0) -> 0 | C22: =IF('Levantamento dutos'!$B22>Calculos!$Z$3,IF('Levantamento dutos'!$B22<=Calculos!$Z$4,((('Levantamento dutos'!$B22)/100+('Levantamento dutos'!$C22)/100)*2)*'Levantamento dutos'!$D22,0),0) -> 0 | D22: =IF('Levantamento dutos'!$B22>Calculos!$Z$4,IF('Levantamento dutos'!$B22<=Calculos!$Z$5,((('Levantamento dutos'!$B22)/100+('Levantamento dutos'!$C22)/100)*2)*'Levantamento dutos'!$D22,0),0) -> 0 | E22: =IF('Levantamento dutos'!$B22>Calculos!$Z$5,IF('Levantamento dutos'!$B22<=Calculos!$Z$6,((('Levantamento dutos'!$B22)/100+('Levantamento dutos'!$C22)/100)*2)*'Levantamento dutos'!$D22,0),0) -> 0 | F22: =IF('Levantamento dutos'!$B22>Calculos!$Z$7,((('Levantamento dutos'!$B22)/100+('Levantamento dutos'!$C22)/100)*2)*'Levantamento dutos'!$D22,0) -> 0 | G22: =(('Levantamento dutos'!B22+'Levantamento dutos'!C22)/100)*2 -> 0 | H22: =IF(CODE('Levantamento dutos'!$E22)=76,SUM($B22:$F22),0) -> 0 | I22: =IF(CODE('Levantamento dutos'!$E22)=73,SUM($B22:$F22),0) -> 0 | J22: =IF(CODE('Levantamento dutos'!$E22)=80,SUM($B22:$F22),0) -> 0 | K22: =IF(CODE('Levantamento dutos'!$F22)=66,SUM($B22:$F22),0) -> 0 | L22: =IF(CODE('Levantamento dutos'!$F22)=70,SUM($B22:$F22),0) -> 0 | M22: =IF(CODE('Levantamento dutos'!$E22)=84,SUM($B22:$F22),0) -> 0 | N22: =IF(CODE('Levantamento dutos'!$G22)=80,IF('Levantamento dutos'!$B22<=200,('Levantamento dutos'!$D22/'Levantamento dutos'!$G$12*Calculos!$G22*2),0),0) -> 0 | O22: =IF(CODE('Levantamento dutos'!$G22)=80,IF('Levantamento dutos'!$B22>200,('Levantamento dutos'!$D22/'Levantamento dutos'!$G$12*Calculos!$G22*2),0),0) -> 0 | P22: =IF(CODE('Levantamento dutos'!$G22)=67,('Levantamento dutos'!$D22/'Levantamento dutos'!$G$12*Calculos!$G22*2),0) -> 0 | Q22: =IF(CODE('Levantamento dutos'!H22)=83,((('Levantamento dutos'!B22/100)+('Levantamento dutos'!$H$12/1000))+(('Levantamento dutos'!C22/100)+('Levantamento dutos'!$H$12)/1000))*2*'Levantamento dutos'!D22,0) -> 0 | S22: =IF(CODE('Levantamento dutos'!$I22)=83,$Q22,0) -> 0 | T22: =IF(CODE('Levantamento dutos'!$E22)=76,ROUND((('Levantamento dutos'!$D22/5)*(Calculos!$G22+0.2)*1.2),0),0) -> 0 | U22: =IF(CODE('Levantamento dutos'!$E22)=73,ROUND((('Levantamento dutos'!$D22/0.5)*(Calculos!$G22+0.2)*1.2),0),0) -> 0 | V22: =IF(CODE('Levantamento dutos'!$E22)=80,ROUND((('Levantamento dutos'!$D22/0.5)*(Calculos!$G22+0.2)*1.2),0),0) -> 0 | W22: =IF(CODE('Levantamento dutos'!$E22)=76,'Levantamento dutos'!$D22/0.5*1.5,0) -> 0 | X22: =IF(CODE('Levantamento dutos'!$E22)=73,'Levantamento dutos'!$D22/0.5*1.5,0) -> 0 | Y22: =IF(CODE('Levantamento dutos'!$E22)=80,'Levantamento dutos'!$D22/0.5*1.5,0) -> 0 | Z22: =IF(CODE('Levantamento dutos'!$E22)=76,ROUND(('Levantamento dutos'!$D22)+('Levantamento dutos'!$D22*Calculos!$G22*2)*1.1,0),0) -> 0 | AA22: =IF(CODE('Levantamento dutos'!$G22)=80,('Levantamento dutos'!$D22/'Levantamento dutos'!$G$12)*8,0) -> 0 | AB22: =IF(CODE('Levantamento dutos'!$G22)=80,IF('Levantamento dutos'!$B22>30,('Levantamento dutos'!$D22/'Levantamento dutos'!$G$12)*4,0),0) -> 0 | AC22: =IF('Levantamento dutos'!$B22>220,('Levantamento dutos'!$D22/'Levantamento dutos'!$G$12*Calculos!$G22*2),0) -> 0 | AD22: =IF(CODE('Levantamento dutos'!$E22)=73,((('Levantamento dutos'!$E$12/1000)+0.02)*'Levantamento dutos'!$D22)*4*1.3,0) -> 0 | AE22: =IF(CODE('Levantamento dutos'!$E22)=80,((('Levantamento dutos'!$E$12/1000)+0.02)*'Levantamento dutos'!$D22)*4*1.3,0) -> 0
B23: =IF('Levantamento dutos'!$B23<=Calculos!$Z$3,((('Levantamento dutos'!$B23)/100+('Levantamento dutos'!$C23)/100)*2)*'Levantamento dutos'!$D23,0) -> 0 | C23: =IF('Levantamento dutos'!$B23>Calculos!$Z$3,IF('Levantamento dutos'!$B23<=Calculos!$Z$4,((('Levantamento dutos'!$B23)/100+('Levantamento dutos'!$C23)/100)*2)*'Levantamento dutos'!$D23,0),0) -> 0 | D23: =IF('Levantamento dutos'!$B23>Calculos!$Z$4,IF('Levantamento dutos'!$B23<=Calculos!$Z$5,((('Levantamento dutos'!$B23)/100+('Levantamento dutos'!$C23)/100)*2)*'Levantamento dutos'!$D23,0),0) -> 0 | E23: =IF('Levantamento dutos'!$B23>Calculos!$Z$5,IF('Levantamento dutos'!$B23<=Calculos!$Z$6,((('Levantamento dutos'!$B23)/100+('Levantamento dutos'!$C23)/100)*2)*'Levantamento dutos'!$D23,0),0) -> 0 | F23: =IF('Levantamento dutos'!$B23>Calculos!$Z$7,((('Levantamento dutos'!$B23)/100+('Levantamento dutos'!$C23)/100)*2)*'Levantamento dutos'!$D23,0) -> 0 | G23: =(('Levantamento dutos'!B23+'Levantamento dutos'!C23)/100)*2 -> 0 | H23: =IF(CODE('Levantamento dutos'!$E23)=76,SUM($B23:$F23),0) -> 0 | I23: =IF(CODE('Levantamento dutos'!$E23)=73,SUM($B23:$F23),0) -> 0 | J23: =IF(CODE('Levantamento dutos'!$E23)=80,SUM($B23:$F23),0) -> 0 | K23: =IF(CODE('Levantamento dutos'!$F23)=66,SUM($B23:$F23),0) -> 0 | L23: =IF(CODE('Levantamento dutos'!$F23)=70,SUM($B23:$F23),0) -> 0 | M23: =IF(CODE('Levantamento dutos'!$E23)=84,SUM($B23:$F23),0) -> 0 | N23: =IF(CODE('Levantamento dutos'!$G23)=80,IF('Levantamento dutos'!$B23<=200,('Levantamento dutos'!$D23/'Levantamento dutos'!$G$12*Calculos!$G23*2),0),0) -> 0 | O23: =IF(CODE('Levantamento dutos'!$G23)=80,IF('Levantamento dutos'!$B23>200,('Levantamento dutos'!$D23/'Levantamento dutos'!$G$12*Calculos!$G23*2),0),0) -> 0 | P23: =IF(CODE('Levantamento dutos'!$G23)=67,('Levantamento dutos'!$D23/'Levantamento dutos'!$G$12*Calculos!$G23*2),0) -> 0 | Q23: =IF(CODE('Levantamento dutos'!H23)=83,((('Levantamento dutos'!B23/100)+('Levantamento dutos'!$H$12/1000))+(('Levantamento dutos'!C23/100)+('Levantamento dutos'!$H$12)/1000))*2*'Levantamento dutos'!D23,0) -> 0 | S23: =IF(CODE('Levantamento dutos'!$I23)=83,$Q23,0) -> 0 | T23: =IF(CODE('Levantamento dutos'!$E23)=76,ROUND((('Levantamento dutos'!$D23/5)*(Calculos!$G23+0.2)*1.2),0),0) -> 0 | U23: =IF(CODE('Levantamento dutos'!$E23)=73,ROUND((('Levantamento dutos'!$D23/0.5)*(Calculos!$G23+0.2)*1.2),0),0) -> 0 | V23: =IF(CODE('Levantamento dutos'!$E23)=80,ROUND((('Levantamento dutos'!$D23/0.5)*(Calculos!$G23+0.2)*1.2),0),0) -> 0 | W23: =IF(CODE('Levantamento dutos'!$E23)=76,'Levantamento dutos'!$D23/0.5*1.5,0) -> 0 | X23: =IF(CODE('Levantamento dutos'!$E23)=73,'Levantamento dutos'!$D23/0.5*1.5,0) -> 0 | Y23: =IF(CODE('Levantamento dutos'!$E23)=80,'Levantamento dutos'!$D23/0.5*1.5,0) -> 0 | Z23: =IF(CODE('Levantamento dutos'!$E23)=76,ROUND(('Levantamento dutos'!$D23)+('Levantamento dutos'!$D23*Calculos!$G23*2)*1.1,0),0) -> 0 | AA23: =IF(CODE('Levantamento dutos'!$G23)=80,('Levantamento dutos'!$D23/'Levantamento dutos'!$G$12)*8,0) -> 0 | AB23: =IF(CODE('Levantamento dutos'!$G23)=80,IF('Levantamento dutos'!$B23>30,('Levantamento dutos'!$D23/'Levantamento dutos'!$G$12)*4,0),0) -> 0 | AC23: =IF('Levantamento dutos'!$B23>220,('Levantamento dutos'!$D23/'Levantamento dutos'!$G$12*Calculos!$G23*2),0) -> 0 | AD23: =IF(CODE('Levantamento dutos'!$E23)=73,((('Levantamento dutos'!$E$12/1000)+0.02)*'Levantamento dutos'!$D23)*4*1.3,0) -> 0 | AE23: =IF(CODE('Levantamento dutos'!$E23)=80,((('Levantamento dutos'!$E$12/1000)+0.02)*'Levantamento dutos'!$D23)*4*1.3,0) -> 0
B24: =IF('Levantamento dutos'!$B24<=Calculos!$Z$3,((('Levantamento dutos'!$B24)/100+('Levantamento dutos'!$C24)/100)*2)*'Levantamento dutos'!$D24,0) -> 0 | C24: =IF('Levantamento dutos'!$B24>Calculos!$Z$3,IF('Levantamento dutos'!$B24<=Calculos!$Z$4,((('Levantamento dutos'!$B24)/100+('Levantamento dutos'!$C24)/100)*2)*'Levantamento dutos'!$D24,0),0) -> 0 | D24: =IF('Levantamento dutos'!$B24>Calculos!$Z$4,IF('Levantamento dutos'!$B24<=Calculos!$Z$5,((('Levantamento dutos'!$B24)/100+('Levantamento dutos'!$C24)/100)*2)*'Levantamento dutos'!$D24,0),0) -> 0 | E24: =IF('Levantamento dutos'!$B24>Calculos!$Z$5,IF('Levantamento dutos'!$B24<=Calculos!$Z$6,((('Levantamento dutos'!$B24)/100+('Levantamento dutos'!$C24)/100)*2)*'Levantamento dutos'!$D24,0),0) -> 0 | F24: =IF('Levantamento dutos'!$B24>Calculos!$Z$7,((('Levantamento dutos'!$B24)/100+('Levantamento dutos'!$C24)/100)*2)*'Levantamento dutos'!$D24,0) -> 0 | G24: =(('Levantamento dutos'!B24+'Levantamento dutos'!C24)/100)*2 -> 0 | H24: =IF(CODE('Levantamento dutos'!$E24)=76,SUM($B24:$F24),0) -> 0 | I24: =IF(CODE('Levantamento dutos'!$E24)=73,SUM($B24:$F24),0) -> 0 | J24: =IF(CODE('Levantamento dutos'!$E24)=80,SUM($B24:$F24),0) -> 0 | K24: =IF(CODE('Levantamento dutos'!$F24)=66,SUM($B24:$F24),0) -> 0 | L24: =IF(CODE('Levantamento dutos'!$F24)=70,SUM($B24:$F24),0) -> 0 | M24: =IF(CODE('Levantamento dutos'!$E24)=84,SUM($B24:$F24),0) -> 0 | N24: =IF(CODE('Levantamento dutos'!$G24)=80,IF('Levantamento dutos'!$B24<=200,('Levantamento dutos'!$D24/'Levantamento dutos'!$G$12*Calculos!$G24*2),0),0) -> 0 | O24: =IF(CODE('Levantamento dutos'!$G24)=80,IF('Levantamento dutos'!$B24>200,('Levantamento dutos'!$D24/'Levantamento dutos'!$G$12*Calculos!$G24*2),0),0) -> 0 | P24: =IF(CODE('Levantamento dutos'!$G24)=67,('Levantamento dutos'!$D24/'Levantamento dutos'!$G$12*Calculos!$G24*2),0) -> 0 | Q24: =IF(CODE('Levantamento dutos'!H24)=83,((('Levantamento dutos'!B24/100)+('Levantamento dutos'!$H$12/1000))+(('Levantamento dutos'!C24/100)+('Levantamento dutos'!$H$12)/1000))*2*'Levantamento dutos'!D24,0) -> 0 | S24: =IF(CODE('Levantamento dutos'!$I24)=83,$Q24,0) -> 0 | T24: =IF(CODE('Levantamento dutos'!$E24)=76,ROUND((('Levantamento dutos'!$D24/5)*(Calculos!$G24+0.2)*1.2),0),0) -> 0 | U24: =IF(CODE('Levantamento dutos'!$E24)=73,ROUND((('Levantamento dutos'!$D24/0.5)*(Calculos!$G24+0.2)*1.2),0),0) -> 0 | V24: =IF(CODE('Levantamento dutos'!$E24)=80,ROUND((('Levantamento dutos'!$D24/0.5)*(Calculos!$G24+0.2)*1.2),0),0) -> 0 | W24: =IF(CODE('Levantamento dutos'!$E24)=76,'Levantamento dutos'!$D24/0.5*1.5,0) -> 0 | X24: =IF(CODE('Levantamento dutos'!$E24)=73,'Levantamento dutos'!$D24/0.5*1.5,0) -> 0 | Y24: =IF(CODE('Levantamento dutos'!$E24)=80,'Levantamento dutos'!$D24/0.5*1.5,0) -> 0 | Z24: =IF(CODE('Levantamento dutos'!$E24)=76,ROUND(('Levantamento dutos'!$D24)+('Levantamento dutos'!$D24*Calculos!$G24*2)*1.1,0),0) -> 0 | AA24: =IF(CODE('Levantamento dutos'!$G24)=80,('Levantamento dutos'!$D24/'Levantamento dutos'!$G$12)*8,0) -> 0 | AB24: =IF(CODE('Levantamento dutos'!$G24)=80,IF('Levantamento dutos'!$B24>30,('Levantamento dutos'!$D24/'Levantamento dutos'!$G$12)*4,0),0) -> 0 | AC24: =IF('Levantamento dutos'!$B24>220,('Levantamento dutos'!$D24/'Levantamento dutos'!$G$12*Calculos!$G24*2),0) -> 0 | AD24: =IF(CODE('Levantamento dutos'!$E24)=73,((('Levantamento dutos'!$E$12/1000)+0.02)*'Levantamento dutos'!$D24)*4*1.3,0) -> 0 | AE24: =IF(CODE('Levantamento dutos'!$E24)=80,((('Levantamento dutos'!$E$12/1000)+0.02)*'Levantamento dutos'!$D24)*4*1.3,0) -> 0
B25: =IF('Levantamento dutos'!$B25<=Calculos!$Z$3,((('Levantamento dutos'!$B25)/100+('Levantamento dutos'!$C25)/100)*2)*'Levantamento dutos'!$D25,0) -> 0 | C25: =IF('Levantamento dutos'!$B25>Calculos!$Z$3,IF('Levantamento dutos'!$B25<=Calculos!$Z$4,((('Levantamento dutos'!$B25)/100+('Levantamento dutos'!$C25)/100)*2)*'Levantamento dutos'!$D25,0),0) -> 0 | D25: =IF('Levantamento dutos'!$B25>Calculos!$Z$4,IF('Levantamento dutos'!$B25<=Calculos!$Z$5,((('Levantamento dutos'!$B25)/100+('Levantamento dutos'!$C25)/100)*2)*'Levantamento dutos'!$D25,0),0) -> 0 | E25: =IF('Levantamento dutos'!$B25>Calculos!$Z$5,IF('Levantamento dutos'!$B25<=Calculos!$Z$6,((('Levantamento dutos'!$B25)/100+('Levantamento dutos'!$C25)/100)*2)*'Levantamento dutos'!$D25,0),0) -> 0 | F25: =IF('Levantamento dutos'!$B25>Calculos!$Z$7,((('Levantamento dutos'!$B25)/100+('Levantamento dutos'!$C25)/100)*2)*'Levantamento dutos'!$D25,0) -> 0 | G25: =(('Levantamento dutos'!B25+'Levantamento dutos'!C25)/100)*2 -> 0 | H25: =IF(CODE('Levantamento dutos'!$E25)=76,SUM($B25:$F25),0) -> 0 | I25: =IF(CODE('Levantamento dutos'!$E25)=73,SUM($B25:$F25),0) -> 0 | J25: =IF(CODE('Levantamento dutos'!$E25)=80,SUM($B25:$F25),0) -> 0 | K25: =IF(CODE('Levantamento dutos'!$F25)=66,SUM($B25:$F25),0) -> 0 | L25: =IF(CODE('Levantamento dutos'!$F25)=70,SUM($B25:$F25),0) -> 0 | M25: =IF(CODE('Levantamento dutos'!$E25)=84,SUM($B25:$F25),0) -> 0 | N25: =IF(CODE('Levantamento dutos'!$G25)=80,IF('Levantamento dutos'!$B25<=200,('Levantamento dutos'!$D25/'Levantamento dutos'!$G$12*Calculos!$G25*2),0),0) -> 0 | O25: =IF(CODE('Levantamento dutos'!$G25)=80,IF('Levantamento dutos'!$B25>200,('Levantamento dutos'!$D25/'Levantamento dutos'!$G$12*Calculos!$G25*2),0),0) -> 0 | P25: =IF(CODE('Levantamento dutos'!$G25)=67,('Levantamento dutos'!$D25/'Levantamento dutos'!$G$12*Calculos!$G25*2),0) -> 0 | Q25: =IF(CODE('Levantamento dutos'!H25)=83,((('Levantamento dutos'!B25/100)+('Levantamento dutos'!$H$12/1000))+(('Levantamento dutos'!C25/100)+('Levantamento dutos'!$H$12)/1000))*2*'Levantamento dutos'!D25,0) -> 0 | S25: =IF(CODE('Levantamento dutos'!$I25)=83,$Q25,0) -> 0 | T25: =IF(CODE('Levantamento dutos'!$E25)=76,ROUND((('Levantamento dutos'!$D25/5)*(Calculos!$G25+0.2)*1.2),0),0) -> 0 | U25: =IF(CODE('Levantamento dutos'!$E25)=73,ROUND((('Levantamento dutos'!$D25/0.5)*(Calculos!$G25+0.2)*1.2),0),0) -> 0 | V25: =IF(CODE('Levantamento dutos'!$E25)=80,ROUND((('Levantamento dutos'!$D25/0.5)*(Calculos!$G25+0.2)*1.2),0),0) -> 0 | W25: =IF(CODE('Levantamento dutos'!$E25)=76,'Levantamento dutos'!$D25/0.5*1.5,0) -> 0 | X25: =IF(CODE('Levantamento dutos'!$E25)=73,'Levantamento dutos'!$D25/0.5*1.5,0) -> 0 | Y25: =IF(CODE('Levantamento dutos'!$E25)=80,'Levantamento dutos'!$D25/0.5*1.5,0) -> 0 | Z25: =IF(CODE('Levantamento dutos'!$E25)=76,ROUND(('Levantamento dutos'!$D25)+('Levantamento dutos'!$D25*Calculos!$G25*2)*1.1,0),0) -> 0 | AA25: =IF(CODE('Levantamento dutos'!$G25)=80,('Levantamento dutos'!$D25/'Levantamento dutos'!$G$12)*8,0) -> 0 | AB25: =IF(CODE('Levantamento dutos'!$G25)=80,IF('Levantamento dutos'!$B25>30,('Levantamento dutos'!$D25/'Levantamento dutos'!$G$12)*4,0),0) -> 0 | AC25: =IF('Levantamento dutos'!$B25>220,('Levantamento dutos'!$D25/'Levantamento dutos'!$G$12*Calculos!$G25*2),0) -> 0 | AD25: =IF(CODE('Levantamento dutos'!$E25)=73,((('Levantamento dutos'!$E$12/1000)+0.02)*'Levantamento dutos'!$D25)*4*1.3,0) -> 0 | AE25: =IF(CODE('Levantamento dutos'!$E25)=80,((('Levantamento dutos'!$E$12/1000)+0.02)*'Levantamento dutos'!$D25)*4*1.3,0) -> 0
